Traceback (most recent call last):
  File "/Users/luweizheng/anaconda3/envs/dispy/lib/python3.11/site-packages/jupyter_cache/executors/utils.py", line 58, in single_nb_execution
    executenb(
  File "/Users/luweizheng/anaconda3/envs/dispy/lib/python3.11/site-packages/nbclient/client.py", line 1305, in execute
    return NotebookClient(nb=nb, resources=resources, km=km, **kwargs).execute()
           ^^^^^^^^^^^^^^^^^^^^^^^^^^^^^^^^^^^^^^^^^^^^^^^^^^^^^^^^^^^^^^^^^^^^^
  File "/Users/luweizheng/anaconda3/envs/dispy/lib/python3.11/site-packages/jupyter_core/utils/__init__.py", line 173, in wrapped
    return loop.run_until_complete(inner)
           ^^^^^^^^^^^^^^^^^^^^^^^^^^^^^^
  File "/Users/luweizheng/anaconda3/envs/dispy/lib/python3.11/asyncio/base_events.py", line 653, in run_until_complete
    return future.result()
           ^^^^^^^^^^^^^^^
  File "/Users/luweizheng/anaconda3/envs/dispy/lib/python3.11/site-packages/nbclient/client.py", line 705, in async_execute
    await self.async_execute_cell(
  File "/Users/luweizheng/anaconda3/envs/dispy/lib/python3.11/site-packages/nbclient/client.py", line 1058, in async_execute_cell
    await self._check_raise_for_error(cell, cell_index, exec_reply)
  File "/Users/luweizheng/anaconda3/envs/dispy/lib/python3.11/site-packages/nbclient/client.py", line 914, in _check_raise_for_error
    raise CellExecutionError.from_cell_and_msg(cell, exec_reply_content)
nbclient.exceptions.CellExecutionError: An error occurred while executing the following cell:
------------------
import logging
import math
import os
import random
import time
from pathlib import Path
from typing import List, Tuple
import numpy as np
import pandas as pd
import matplotlib.pyplot as plt
from PIL import Image
import torch
import torchvision
from torchvision import transforms as T
%matplotlib inline
import matplotlib_inline
matplotlib_inline.backend_inline.set_matplotlib_formats('svg')

import ray
------------------


[0;31m---------------------------------------------------------------------------[0m
[0;31mModuleNotFoundError[0m                       Traceback (most recent call last)
Cell [0;32mIn[1], line 13[0m
[1;32m     11[0m [38;5;28;01mfrom[39;00m [38;5;21;01mPIL[39;00m [38;5;28;01mimport[39;00m Image
[1;32m     12[0m [38;5;28;01mimport[39;00m [38;5;21;01mtorch[39;00m
[0;32m---> 13[0m [38;5;28;01mimport[39;00m [38;5;21;01mtorchvision[39;00m
[1;32m     14[0m [38;5;28;01mfrom[39;00m [38;5;21;01mtorchvision[39;00m [38;5;28;01mimport[39;00m transforms [38;5;28;01mas[39;00m T
[1;32m     15[0m get_ipython()[38;5;241m.[39mrun_line_magic([38;5;124m'[39m[38;5;124mmatplotlib[39m[38;5;124m'[39m, [38;5;124m'[39m[38;5;124minline[39m[38;5;124m'[39m)

[0;31mModuleNotFoundError[0m: No module named 'torchvision'

